<?xml version="1.0" encoding="utf-8"?>
<robot
  name="robot">
  <link name = "base_footprint" />
  <joint
    name="back_foot_joint"
    type="fixed">
    <origin
      xyz="0 0 0"
      rpy="0 0 0" />
    <parent
      link="base_footprint" />
    <child
      link="base_link" />
  </joint>
  <link
    name="base_link">
    <inertial>
      <origin
        xyz="0 0 0"
        rpy="0 0 0" />
      <mass
        value="10" />
      <inertia
        ixx="0.01"
        ixy="0"
        ixz="0"
        iyy="0.01"
        iyz="0"
        izz="0.01" />
    </inertial>
    <visual>
      <origin
        xyz="0 0 0"
        rpy="0 0 1.57" />
      <geometry>
        <mesh
          filename="package://explorer/meshes/base_link.stl" scale="0.05 0.05 0.05"/> 
      </geometry>
      <material
        name="">
        <color
          rgba="0.898039215686275 0.917647058823529 0.929411764705882 1" />
      </material>
    </visual>
    <collision>
       <origin
        xyz="0 0 0"
        rpy="0 0 1.57" />
      <geometry>
        <mesh
          filename="package://explorer/meshes/base_link.stl" scale="0.05 0.05 0.05"/> 
      </geometry>
    </collision>
  </link>

  <link
    name="back_right">
    <inertial>
      <origin
        xyz="0 0 0"
        rpy="0 0 0" />
      <mass
        value="0.1" />
      <inertia
        ixx="0.01"
        ixy="0"
        ixz="0"
        iyy="0.01"
        iyz="0"
        izz="0.01" />
    </inertial>
    <visual>
      <origin
        xyz="0.255 0.25 -0.065"
        rpy="0 0 1.57"/>
      <geometry>
        <mesh
          filename="package://explorer/meshes/Wheel.stl" scale="0.05 0.05 0.05"/>
      </geometry>
      <material
        name="">
        <color
          rgba="0.792156862745098 0.819607843137255 0.933333333333333 1" />
      </material>
    </visual>
    <collision>
      <origin
        xyz="0 0 0.0"
        rpy="0 1.57 1.57" />
      <geometry>
    <cylinder length="0.05" radius="0.1"/>
      </geometry>
    </collision>
  </link>
  <joint
    name="back_right_joint"
    type="continuous">
    <origin
      xyz="-0.255 -0.25 0.065"
      rpy="0 0 0" />
    <parent
      link="base_link" />
    <child
      link="back_right" />
    <axis
      xyz="0 1 0" />
  </joint>

  <link
    name="front_right">
    <inertial>
      <origin
        xyz="0 0 0"
        rpy="0 0 0" />
      <mass
        value="0.1" />
      <inertia
        ixx="0.01"
        ixy="0"
        ixz="0"
        iyy="0.01"
        iyz="0"
        izz="0.01"/>
    </inertial>
    <visual>
      <origin
        xyz="0.255 0.25 -0.065"
        rpy="0 0 1.57"/>
      <geometry>
        <mesh
          filename="package://explorer/meshes/Wheel.stl" scale="0.05 0.05 0.05"/>
      </geometry>
      <material
        name="">
        <color
          rgba="0.792156862745098 0.819607843137255 0.933333333333333 1" />
      </material>
    </visual>
    <collision>
      <origin
        xyz="0 0 0.0"
        rpy="0 1.57 1.57" />
      <geometry>
    <cylinder length="0.05" radius="0.1"/>
      </geometry>
    </collision>
  </link>
  <joint
    name="front_right_joint"
    type="continuous">
    <origin
      xyz="0.255 -0.25 0.065"
      rpy="0 0 0" />
    <parent
      link="base_link" />
    <child
      link="front_right" />
    <axis
      xyz="0 1 0" />
  </joint>

  <link
    name="back_left">
    <inertial>
      <origin
        xyz="0 0 0"
        rpy="0 0 0" />
      <mass
        value="0.1" />
      <inertia
        ixx="0.01"
        ixy="0"
        ixz="0"
        iyy="0.01"
        iyz="0"
        izz="0.01" />
    </inertial>
    <visual>
      <origin
        xyz="0.255 0.25 -0.065"
        rpy="0 0 1.57" />
      <geometry>
        <mesh
          filename="package://explorer/meshes/Wheel1.stl" scale="0.05 0.05 0.05"/>
      </geometry>
      <material
        name="">
        <color
          rgba="0.792156862745098 0.819607843137255 0.933333333333333 1" />
      </material>
    </visual>
    <collision>
      <origin
        xyz="0 0 0.0"
        rpy="0 1.57 1.57" />
      <geometry>
    <cylinder length="0.05" radius="0.1"/>
      </geometry>
    </collision>
  </link>
  <joint
    name="back_left_joint"
    type="continuous">
    <origin
      xyz="-0.255 0.25 0.065"
      rpy="0 0 0" />
    <parent
      link="base_link" />
    <child
      link="back_left" />
    <axis
      xyz="0 1 0" />
  </joint>

  <link
    name="front_left">
    <inertial>
      <origin
        xyz="0 0 0"
        rpy="0 0 0" />
      <mass
        value="0.1" />
      <inertia
        ixx="0.01"
        ixy="0"
        ixz="0"
        iyy="0.01"
        iyz="0"
        izz="0.01"/>
    </inertial>
    <visual>
      <origin
        xyz="0.255 0.25 -0.065"
        rpy="0 0 1.57" />
      <geometry>
        <mesh
          filename="package://explorer/meshes/Wheel.stl" scale="0.05 0.05 0.05"/>
      </geometry>
      <material
        name="">
        <color
          rgba="0.792156862745098 0.819607843137255 0.933333333333333 1" />
      </material>
    </visual>
    <collision>
      <origin
        xyz="0 0 0.0"
        rpy="0 1.57 1.57"/>
      <geometry>
    <cylinder length="0.05" radius="0.1"/>
      </geometry>
    </collision>
  </link>
  <joint
    name="front_left_joint"
    type="continuous">
    <origin
      xyz="0.255 0.25 0.065"
      rpy="0 0 0"  />
    <parent
      link="base_link" />
    <child
      link="front_left" />
    <axis
      xyz="0 1 0" />
  </joint>
  

 <link
    name="laser">
    <inertial>
      <origin
        xyz="0 0 0"
        rpy="0 0 0" />
      <mass
        value="0" />
      <inertia
        ixx="0.01"
        ixy="0"
        ixz="0"
        iyy="0.01"
        iyz="0"
        izz="0.01" />
    </inertial>
    <visual>
      <origin
        xyz="0 0 0"
        rpy="0 0 0" />
      <geometry>
        <mesh
          filename="package://explorer/meshes/rplidar.stl" />
      </geometry>
      <material
        name="">
        <color
          rgba="0.792156862745098 0.819607843137255 0.933333333333333 1" />
      </material>
    </visual>
    <collision>
      <origin
        xyz="0 0 0"
        rpy="0 0 0" />
      <geometry>
        <mesh
          filename="package://explorer/meshes/rplidar.stl" />
      </geometry>
    </collision>
  </link>
  <joint
    name="lidar_base"
    type="fixed">
    <origin
      xyz="0.25 0 0.25"
      rpy="0 0 0" />
    <parent
      link="base_link" />
    <child
      link="laser" />
    <axis
      xyz="0 0 0" />
  </joint>

  <gazebo reference="laser">
 <material>Gazebo/Green</material>
</gazebo>

  <gazebo reference="camera">
 <material>Gazebo/Blue</material>
</gazebo>

  <gazebo reference="front_right">
 <material>Gazebo/Black</material>
</gazebo>

  <gazebo reference="front_left">
 <material>Gazebo/Black</material>
</gazebo>

  <gazebo reference="back_right">
 <material>Gazebo/Black</material>
</gazebo>

  <gazebo reference="back_left">
 <material>Gazebo/Black</material>
</gazebo>

  <gazebo reference="base_link">
 <material>Gazebo/White</material>
</gazebo>


<gazebo reference="laser">
    <sensor type="ray" name="lds_lfcd_sensor">
      <pose>0 0 0 0 0 0</pose>
      <update_rate>5</update_rate>
      <ray>
        <scan>
          <horizontal>
            <samples>360</samples>
            <resolution>1</resolution>
            <min_angle>0.0</min_angle>
            <max_angle>6.28319</max_angle>
          </horizontal>
        </scan>
        <range>
          <min>0.120</min>
          <max>30.0</max>
          <resolution>0.015</resolution>
        </range>
        <noise>
          <type>gaussian</type>
          <mean>0.0</mean>
          <stddev>0.01</stddev>
        </noise>
      </ray>
      <plugin name="gazebo_ros_lds_lfcd_controller" filename="libgazebo_ros_laser.so">
        <topicName>scan</topicName>
        <frameName>laser</frameName>
      </plugin>
    </sensor>
  </gazebo>

<!-- Skid Steering Drive -->
<!-- <gazebo>
  <plugin name="skid_steer_drive_controller" filename="libgazebo_ros_skid_steer_drive.so">
    <updateRate>100.0</updateRate>
    <robotNamespace>/</robotNamespace>
    <leftFrontJoint>front_left_joint</leftFrontJoint>
    <rightFrontJoint>front_right_joint</rightFrontJoint>
    <leftRearJoint>back_left_joint</leftRearJoint>
    <rightRearJoint>back_right_joint</rightRearJoint>
    <wheelSeparation>0.7</wheelSeparation>
    <wheelDiameter>0.2</wheelDiameter>
    <robotBaseFrame>base_link</robotBaseFrame>
    <torque>1000</torque>
    <topicName>cmd_vel</topicName>
    <broadcastTF>false</broadcastTF>
       <odometryTopic>odom</odometryTopic>
    <odometryFrame>odom</odometryFrame>
        <covariance_x>0.001</covariance_x> 
    <covariance_y>0.001</covariance_y> 
    <covariance_yaw>0.01</covariance_yaw> 
  </plugin>
</gazebo> -->

<gazebo>
  <plugin name="differential_drive_controller" filename="libgazebo_ros_diff_drive.so">
    <updateRate>30</updateRate>
    <leftJoint>back_left_joint</leftJoint>
    <rightJoint>back_right_joint</rightJoint>
    <wheelSeparation>0.5380</wheelSeparation>
    <wheelDiameter>0.2</wheelDiameter>
    <wheelAcceleration>1.0</wheelAcceleration>
    <wheelTorque>50</wheelTorque>
    <commandTopic>cmd_vel</commandTopic>
    <odometryTopic>odom</odometryTopic>
    <odometryFrame>odom</odometryFrame>
    <robotBaseFrame>base_footprint</robotBaseFrame>
    <odometrySource>1</odometrySource>
    <publishWheelTF>true</publishWheelTF>
    <publishOdom>true</publishOdom>
    <publishWheelJointState>true</publishWheelJointState>
    <legacyMode>false</legacyMode>
  </plugin>
</gazebo>

<gazebo>
  <plugin name="differential_drive_controller" filename="libgazebo_ros_diff_drive.so">
    <updateRate>30</updateRate>
    <leftJoint>front_left_joint</leftJoint>
    <rightJoint>front_right_joint</rightJoint>
    <wheelSeparation>0.5380</wheelSeparation>
    <wheelDiameter>0.2</wheelDiameter>
    <wheelAcceleration>1.0</wheelAcceleration>
    <wheelTorque>50</wheelTorque>
    <commandTopic>cmd_vel</commandTopic>
    <odometryTopic>odom</odometryTopic>
    <odometryFrame>odom</odometryFrame>
    <robotBaseFrame>base_footprint</robotBaseFrame>
    <odometrySource>1</odometrySource>
    <publishWheelTF>true</publishWheelTF>
    <publishOdom>true</publishOdom>
    <publishWheelJointState>true</publishWheelJointState>
    <legacyMode>false</legacyMode>
  </plugin>
</gazebo>

</robot>

